Workbook

Sheet Cover
A1: Bruno AC Services LLC
A2: Bruno AC Estimating
A3: HVAC / Air Conditioning Estimating Workbook — Texas 2026
A5: Company | B5: Bruno AC Services LLC
A6: City / State | B6: Austin, TX
A7: Demo job | B7: Sample Residence — AC Changeout
A8: Proposal # | B8: AC-0926-001
A9: Date | B9: 2026-09-11
A11: Method A (Summary)
A12: sales = cost × (1 + OH) / (1 − profit)
A13: OH default | B13: 0.25
A14: Profit of sales default | B14: 0.15
A15: Material markup | B15: 0
A16: Quote Total | B16: ROUND(final sales) + approved Change Orders only
A18: Sheets
A19: Cover — branding & orientation
A20: Quote — customer-facing proposal face
A21: Materials — job takeoff (qty × unitCost, markup 0)
A22: Catalog — Texas HVAC price book (example USD)
A23: LaborEquip — equipment, labor blocks, subs
A24: SmallTools — tool lines rolling into Equip
A25: Summary — Method A OH&P and Quote Total
A26: Workers — burden (quote path) + pay calculator (info only)
A27: TM — Time & Material invoice (NO Method A OH&P)
A28: PnL — Quoted vs Billed vs Actual
A29: ChangeOrders — only Approved adds to Quote Total
... A39: © 2026 Bruno AC Services LLC

Sheet Quote
A1: Bruno AC Services LLC
A2: PROPOSAL / QUOTE
A4: Date | B4: 2026-09-11
A5: Proposal # | B5: AC-0926-001
A6: Job # | B6: AC-0926-001
A7: P.O. #
A8: Work Order #
A9: Quoted by | B9: Estimator
A10: Contact | B10: Homeowner
A11: Customer | B11: Sample Residence — AC Changeout
A12: Job address | B12: 123 Maple Creek Ln
A13: City / State / ZIP | B13: Austin, TX 78745
A14: Reference | B14: Residential heat pump changeout
A16: HVAC job tags (informational — do not drive Method A)
A17: System type | B17: split-heat-pump
A18: Tonnage / BTU | B18: 3 ton / ~36,000 BTU
A19: SEER2 target | B19: 15.2 (OEM published — verify AHRI)
A20: HSPF2 | B20: 7.8
A21: Refrigerant | B21: R-454B (A2L)
A22: Job kind | B22: replace
A23: Duct config | B23: ducted
A24: Haul-away | B24: yes
A26: Scope / description
A27: One year workmanship warranty on installation (manufacturer warranty per OEM).
A28: Work during normal business hours unless otherwise agreed.
A30: Replace existing split system with matched SEER2 heat pump + air handler (R-454B / A2L path).
A31: Includes line set as scoped, pad, disconnect and whip, thermostat, condensate protection, A2L leak-detection sensor.
A32: Recover and haul away existing equipment (service/legacy refrigerant handling by certified tech).
A33: Permit allowance included — final fee by AHJ.
A34: Startup / commissioning and thermostat setup included in labor.
A36: Informational job tags: 3 ton · SEER2 target per OEM AHRI · ducted · replace.
A37: Not a Manual J / Manual S / Manual D design. Load calc and AHRI match by others if required.
A39: Terms
A40: Thank you for your business!
... A45: QUOTE TOTALS (from Summary)
A46: Material Cost | B46: =Summary!D24
A47: Labor Cost | B47: =Summary!D22
A48: Equip Cost | B48: =Summary!D20
A49: Job Cost | B49: =Summary!D28
A50: Sales (exact) | B50: =Summary!D39
...

Sheet Materials
A1: JOB MATERIALS (takeoff)
A2: Material Cost TOTAL | B2: =SUM(H12:H200) | C2: ← feeds Summary!D24
A3: Material markup % | B3: 0 | C3: LOCKED 0 — single margin layer is Summary Method A only
A4: Quoted materials (legacy display = cost when markup 0) | B4: =ROUND(B2*(1+B3),0)
A5: Last price update | B5: 2026-09-11
A6: Note: Extension = Qty × Unit Cost. No auto line-set length, charge, or Manual J.
A11: Qty | B11: ID | C11: Item | D11: Part # | E11: Vendor | F11: Units | G11: Unit Cost | H11: Extension | I11: Category | J11: SEER2 | K11: Refrigerant | L11: Notes
A12: 1 | B12: ac-ou-02 | C12: Split-system heat pump outdoor unit, SEER2/HSPF2-rated (3 ton) | D12: OU-HP-3T | E12: - | F12: ea | G12: 2800 | H12: =A12*G12 | I12: Outdoor units | J12: 15.2 | K12: R-454B
A13: 1 | B13: ac-in-01 | C13: Multiposition air handler matched to outdoor | D13: AHU-3T | E13: - | F13: ea | G13: 1600 | H13: =A13*G13 | I13: Indoor units / air handlers / coils | K13: R-454B
A14: 1 | B14: ac-ls-02 | C14: Insulated line set, 3/8 × 3/4, 25 ft | D14: LS-3874-25 | E14: - | F14: ea | G14: 185 | H14: =A14*G14 | I14: Line sets & fittings
A15: 1 | B15: ac-ls-07 | C15: Filter-drier (liquid line) | D15: FD-LL | E15: - | F15: ea | G15: 48 | H15: =A15*G15 | I15: Line sets & fittings | K15: R-454B
A16: 1 | B16: ac-pd-02 | C16: Plastic / composite condenser pad | D16: PAD-COMP | E16: - | F16: ea | G16: 89 | H16: =A16*G16 | I16: Pads, stands & mounts
A17: 1 | B17: ac-ct-03 | C17: Wi-Fi / connected thermostat | D17: TSTAT-WIFI | E17: - | F17: ea | G17: 220 | H17: =A17*G17 | I17: Controls & thermostats
A18: 1 | B18: ac-cd-03 | C18: Condensate pump | D18: C-PUMP | E18: - | F18: ea | G18: 95 | H18: =A18*G18 | I18: Condensate & drainage
A19: 1 | B19: ac-cd-04 | C19: Float switch (primary / aux) | D19: FLOAT | E19: - | F19: ea | G19: 42 | H19: =A19*G19 | I19: Condensate & drainage
A20: 1 | B20: ac-cd-05 | C20: Secondary / emergency drain pan | D20: SEC-PAN | E20: - | F20: ea | G20: 65 | H20: =A20*G20 | I20: Condensate & drainage
A21: 1 | B21: ac-el-01 | C21: Non-fused AC disconnect | D21: DISC | E21: - | F21: ea | G21: 55 | H21: =A21*G21 | I21: Electrical accessories (HVAC)
A22: 1 | B22: ac-el-02 | C22: Liquid-tight whip | D22: WHIP | E22: - | F22: ea | G22: 48 | H22: =A22*G22 | I22: Electrical accessories (HVAC)
A23: 1 | B23: ac-rf-01 | C23: Virgin refrigerant R-454B (top-off / inventory) | D23: R454B | E23: - | F23: lb | G23: 120 | H23: =A23*G23 | I23: Refrigerant & recovery | K23: R-454B | L23: Qty in lbs — OEM charge + line adder by hand; no auto charge calc
A24: 1 | B24: ac-a2l-01 | C24: A2L refrigerant leak-detection sensor | D24: A2L-SENSOR | E24: - | F24: ea | G24: 175 | H24: =A24*G24 | I24: A2L install extras
A25: 1 | B25: ac-cm-06 | C25: Equipment disposal / haul-away (old R-410A system) | D25: HAUL | E25: - | F25: ea | G25: 275 | H25: =A25*G25 | I25: Consumables / misc & freight
A26: 1 | B26: ac-cm-08 | C26: Permit allowance | D26: PERMIT | E26: - | F26: allow | G26: 175 | H26: =A26*G26 | I26: Consumables / misc & freight
A27: 2 | B27: ac-iq-01 | C27: MERV pleated filter | D27: MERV | E27: - | F27: ea | G27: 18 | H27: =A27*G27 | I27: Filters & IAQ
H28: =IF(OR(A28="",G28=""),"",A28*G28)
H29: =IF(OR(A29="",G29=""),"",A29*G29)
H30: =IF(OR(A30="",G30=""),"",A30*G30)
H31: =IF(OR(A31="",G31=""),"",A31*G31)
H32: =IF(OR(A32="",G32=""),"",A32*G32)
H33: =IF(OR(A33="",G33=""),"",A33*G33)
H34: =IF(OR(A34="",G34=""),"",A34*G34)
H35: =IF(OR(A35="",G35=""),"",A35*G35)
H36: =IF(OR(A36="",G36=""),"",A36*G36)
H37: =IF(OR(A37="",G37=""),"",A37*G37)
H38: =IF(OR(A38="",G38=""),"",A38*G38)
H39: =IF(OR(A39="",G39=""),"",A39*G39)
... H61: =IF(OR(A61="",G61=""),"",A61*G61)

Sheet Catalog
A1: HVAC CATALOG — Texas estimating price book (example USD)
A2: R-454B / A2L = new-install path; R-410A = service/legacy. Prices are ballpark defaults — verify vendor quotes / AHRI. Not a design tool.
A3: Categories cover Outdoor, Indoor, Package, Mini-split, Line sets, Refrigerant, A2L extras, Condensate, Duct, Controls, Electrical accessories, Pads, Filters/IAQ, Insulation, Consumables.
A5: ID | B5: Item | C5: Part # | D5: Vendor | E5: Units | F5: Unit Cost | G5: Category | H5: SEER2 | I5: HSPF2 | J5: Refrigerant | K5: Notes / Flags
A6: ac-ou-01 | B6: Split-system condensing unit, cooling-only, SEER2-rated (TX Southeast) | C6: OU-AC-SEER2 | D6: - | E6: ea | F6: 2400 | G6: Outdoor units | H6: 14.3+ | J6: R-454B | K6: TX install SEER2 floors: <45 kBtu 14.3 / ≥45 kBtu 13.8. National 13.4 is manufacture floor — not TX install. EER2 regional adders are Southwest (not Texas). | new-install,verify-AHRI
A7: ac-ou-02 | B7: Split-system heat pump outdoor unit, SEER2/HSPF2-rated | C7: OU-HP-SEER2 | D7: - | E7: ea | F7: 2800 | G7: Outdoor units | H7: 14.3+ | I7: 7.5+ | J7: R-454B | K7: Split HP national floors: 14.3 SEER2 / 7.5 HSPF2. Confirm published AHRI ratings. | new-install
A8: ac-ou-03 | B8: Outdoor unit, side-discharge / compact footprint | C8: OU-SIDE | D8: - | E8: ea | F8: 3100 | G8: Outdoor units | K8: Clearances per manufacturer.
A9: ac-ou-04 | B9: Outdoor unit, coastal / corrosion-resistant coil option | C9: OU-COAST | D9: - | E9: ea | F9: 425 | G9: Outdoor units | K9: Gulf/coastal option line — not automatic.
A10: ac-ou-05 | B10: Outdoor unit pad-mount hardware kit | C10: OU-PADKIT | D10: - | E10: ea | F10: 48 | G10: Outdoor units
A11: ac-in-01 | B11: Multiposition air handler (electric heat optional) | C11: AHU-MP | D11: - | E11: ea | F11: 1600 | G11: Indoor units / air handlers / coils | J11: R-454B | K11: new-install
A12: ac-in-02 | B12: Cased evaporator coil (upflow/downflow/horizontal) | C12: COIL-CASED | D12: - | E12: ea | F12: 850 | G12: Indoor units / air handlers / coils | J12: R-454B
A13: ac-in-03 | B13: Uncased coil | C13: COIL-UNC | D13: - | E13: ea | F13: 650 | G13: Indoor units / air handlers / coils
A14: ac-in-04 | B14: Furnace companion coil (cased) | C14: COIL-FURN | D14: - | E14: ea | F14: 780 | G14: Indoor units / air handlers / coils | K14: Gas furnace + AC coil changeouts common in TX.
A15: ac-in-05 | B15: Gas furnace (non-weatherized) — record AFUE | C15: FURN-GAS | D15: - | E15: ea | F15: 2200 | G15: Indoor units / air handlers / coils | K15: Federal AFUE floor 80% now; 95% for units mfr on/after 2028-12-18 (10 CFR 430.32(e)). Informational — does not change Method A.
A16: ac-in-06 | B16: Electric heat kit for air handler | C16: HEATKIT | D16: - | E16: ea | F16: 320 | G16: Indoor units / air handlers / coils | K16: Size by kW; electrical feed by others as scoped.
A17: ac-in-07 | B17: Media filter cabinet (return) | C17: MEDIA-CAB | D17: - | E17: ea | F17: 185 | G17: Indoor units / air handlers / coils
A18: ac-pk-01 | B18: Packaged rooftop / ground AC (cooling-only) | C18: PKG-AC | D18: - | E18: ea | F18: 4200 | G18: Package units | H18: 13.4+ | J18: R-454B | K18: Single-package SEER2 floors differ from splits — verify DOE class.
A19: ac-pk-02 | B19: Packaged heat pump | C19: PKG-HP | D19: - | E19: ea | F19: 4800 | G19: Package units | H19: 13.4+ | I19: 6.7+ | J19: R-454B
A20: ac-pk-03 | B20: Packaged gas/electric (cooling + gas heat) | C20: PKG-GE | D20: - | E20: ea | F20: 5200 | G20: Package units | K20: Confirm local fuel gas / IFGC via TDLR-adopted codes.
A21: ac-pk-04 | B21: Roof curb (adapter / standard) | C21: CURB | D21: - | E21: ea | F21: 450 | G21: Package units
A22: ac-pk-05 | B22: Transition / supply-return duct package for RTU | C22: RTU-DUCT | D22: - | E22: ea | F22: 650 | G22: Package units
A23: ac-ms-01 | B23: Ductless indoor wall / ceiling cassette head | C23: MS-HEAD | D23: - | E23: ea | F23: 650 | G23: Mini-split / multi-zone | J23: R-454B
A24: ac-ms-02 | B24: Ductless outdoor multi-port unit | C24: MS-ODU | D24: - | E24: ea | F24: 2200 | G24: Mini-split / multi-zone | J24: R-454B | K24: Verify EPA / OEM class; VRF dates may differ from split.
A25: ac-ms-03 | B25: Branch box / distributor | C25: MS-BRANCH | D25: - | E25: ea | F25: 380 | G25: Mini-split / multi-zone | K25: Design by others — set qty and price as scoped.
A26: ac-ls-01 | B26: Insulated line set, 1/4 × 3/8, 15–25 ft band | C26: LS-1438 | D26: - | E26: ea | F26: 95 | G26: Line sets & fittings | K26: Do not auto-calc length from tonnage.
A27: ac-ls-02 | B27: Insulated line set, 3/8 × 3/4, 15–25 ft band | C27: LS-3874 | D27: - | E27: ea | F27: 185 | G27: Line sets & fittings
A28: ac-ls-03 | B28: Insulated line set, 3/8 × 7/8, 15–50 ft band | C28: LS-3878 | D28: - | E28: ea | F28: 275 | G28: Line sets & fittings
A29: ac-ls-04 | B29: Soft copper ACR tube (by size) | C29: ACR-CU | D29: - | E29: ft | F29: 4.5 | G29: Line sets & fittings
A30: ac-ls-05 | B30: Flare nuts / flare fittings assortment | C30: FLARE-KIT | D30: - | E30: kit | F30: 35 | G30: Line sets & fittings | K30: A2L / OEM connection method may differ.
A31: ac-ls-06 | B31: Ball valve / service valve (pair) | C31: BV-PAIR | D31: - | E31: ea | F31: 85 | G31: Line sets & fittings
A32: ac-ls-07 | B32: Filter-drier (liquid line), size by system | C32: FD-LL | D32: - | E32: ea | F32: 48 | G32: Line sets & fittings | J32: R-454B
A33: ac-ls-08 | B33: Sight glass / moisture indicator | C33: SG | D33: - | E33: ea | F33: 28 | G33: Line sets & fittings
A34: ac-ls-09 | B34: Line-set wall penetration cover / escutcheon | C34: LS-ESC | D34: - | E34: ea | F34: 18 | G34: Line sets & fittings
A35: ac-ls-10 | B35: UV-resistant line-set paint / jacketing | C35: LS-UV | D35: - | E35: ft | F35: 3.25 | G35: Line sets & fittings
A36: ac-rf-01 | B36: Virgin refrigerant R-454B (cylinder) — new-install A2L path | C36: R454B | D36: - | E36: lb | F36: 120 | G36: Refrigerant & recovery | J36: R-454B | K36: Primary new-install refrigerant for 2026 TX estimating. Mildly flammable A2L — trained techs + compatible tools. No charge calculator. Example estimating default — verify against shop/vendor quotes. | new-install,A2L
A37: ac-rf-02 | B37: Virgin refrigerant R-32 (cylinder) — A2L path | C37: R32 | D37: - | E37: lb | F37: 95 | G37: Refrigerant & recovery | J37: R-32 | K37: Common A2L OEM path. Verify OEM refrigerant. | new-install,A2L
A38: ac-rf-03 | B38: Virgin refrigerant R-410A (cylinder) — SERVICE / LEGACY ONLY | C38: R410A-SVC | D38: - | E38: lb | F38: 75 | G38: Refrigerant & recovery | J38: R-410A | K38: Service/existing systems and remaining legal pre-2025 inventory only. Not default new-install SKU after GWP 700 rules. Confirm EPA Technology Transitions. | service-legacy
A39: ac-rf-04 | B39: Nitrogen (oxygen-free), cylinder | C39: N2 | D39: - | E39: cyl | F39: 45 | G39: Refrigerant & recovery
A40: ac-rf-05 | B40: Recovery cylinder (DOT), refrigerant-class specific | C40: REC-CYL | D40: - | E40: ea | F40: 185 | G40: Refrigerant & recovery | K40: Do not mix classes casually.
A41: ac-rf-06 | B41: Vacuum pump oil | C41: VPOIL | D41: - | E41: qt | F41: 12 | G41: Refrigerant & recovery
...

Sheet LaborEquip
A1: LABOR & EQUIPMENT
A2: TOTAL IN-HOUSE LABOR | B2: =F29+F35+F41+F47+F53 | C2: ← feeds Summary!D22
A4: EQUIPMENT / RENTAL
A5: Equipment Type | B5: Cost | C5: Vendor
A6: Crane / lift allowance | B6: 450 | C6: rental
A7: Recovery machine rental (A2L-capable) | B7: 150 | C7: shop
B8: 0
B9: 0
B10: 0
B11: 0
B12: 0
B13: 0
A14: Small Tools roll-up | B14: =SmallTools!E5
A15: EQUIPMENT COST TOTAL | B15: =SUM(B6:B13)+B14 | C15: ← feeds Summary!D20
A17: SUBCONTRACTORS
A18: Name | B18: Scope | C18: Price
C19: 0
C20: 0
C21: 0
C22: 0
A23: SUBCONTRACTOR TOTAL | B23: =SUM(C19:C22) | C23: ← feeds Summary!D26
A25: LABOR — Lead tech | D25: Burden $/hr | E25: =Workers!C12
A26: Persons (straight) | B26: 1 | C26: Days | D26: 2 | E26: Hrs/day | F26: 8
A27: Sat P / D / H | B27: 0 | C27: 0 | D27: 8 | E27: Sun P / D / H | F27: 0 | G27: 0 | H27: 8 | I27: Weekday OT hrs (>8 hpd)
A28: Straight hrs | B28: =IF(F26>8,B26*D26*8,B26*D26*F26) | C28: OT hrs (Sat ×1.5 burden) | D28: =B27*C27*D27 | E28: DT hrs (Sun ×2 burden) | F28: =F27*G27*H27 | I28: =IF(F26>8,B26*D26*(F26-8),0)
A29: Labor cost | F29: =B28*E25+(I28+D28)*E25*1.5+F28*E25*2
A31: LABOR — Installer | D31: Burden $/hr | E31: =Workers!C13
A32: Persons (straight) | B32: 1 | C32: Days | D32: 2 | E32: Hrs/day | F32: 8
A33: Sat P / D / H | B33: 0 | C33: 0 | D33: 8 | E33: Sun P / D / H | F33: 0 | G33: 0 | H33: 8 | I33: Weekday OT hrs (>8 hpd)
A34: Straight hrs | B34: =IF(F32>8,B32*D32*8,B32*D32*F32) | C34: OT hrs (Sat ×1.5 burden) | D34: =B33*C33*D33 | E34: DT hrs (Sun ×2 burden) | F34: =F33*G33*H33 | I34: =IF(F32>8,B32*D32*(F32-8),0)
A35: Labor cost | F35: =B34*E31+(I34+D34)*E31*1.5+F34*E31*2
A37: LABOR — Helper | D37: Burden $/hr | E37: =Workers!C14
A38: Persons (straight) | B38: 1 | C38: Days | D38: 2 | E38: Hrs/day | F38: 8
A39: Sat P / D / H | B39: 0 | C39: 0 | D39: 8 | E39: Sun P / D / H | F39: 0 | G39: 0 | H39: 8 | I39: Weekday OT hrs (>8 hpd)
A40: Straight hrs | B40: =IF(F38>8,B38*D38*8,B38*D38*F38) | C40: OT hrs (Sat ×1.5 burden) | D40: =B39*C39*D39 | E40: DT hrs (Sun ×2 burden) | F40: =F39*G39*H39 | I40: =IF(F38>8,B38*D38*(F38-8),0)
A41: Labor cost | F41: =B40*E37+(I40+D40)*E37*1.5+F40*E37*2
A43: LABOR — Sheet-metal | D43: Burden $/hr | E43: =Workers!C15
A44: Persons (straight) | B44: 0 | C44: Days | D44: 0 | E44: Hrs/day | F44: 8
A45: Sat P / D / H | B45: 0 | C45: 0 | D45: 8 | E45: Sun P / D / H | F45: 0 | G45: 0 | H45: 8 | I45: Weekday OT hrs (>8 hpd)
A46: Straight hrs | B46: =IF(F44>8,B44*D44*8,B44*D44*F44) | C46: OT hrs (Sat ×1.5 burden) | D46: =B45*C45*D45 | E46: DT hrs (Sun ×2 burden) | F46: =F45*G45*H45 | I46: =IF(F44>8,B44*D44*(F44-8),0)
...

Sheet SmallTools
A1: SMALL TOOLS (rolls into Equip — Method A once)
A2: Do not apply Method A separately to small tools.
A4: Small Tools TOTAL
A5: TOTAL → LaborEquip!B14 | E5: =SUM(F12:F100)
A11: Qty | B11: Description | C11: Supplier | D11: Part | E11: Unit Cost | F11: Extension | G11: Group
A12: 0 | B12: Safety glasses | E12: 8 | F12: =IF(A12="","",A12*E12) | G12: PPE
A13: 0 | B13: Work gloves | E13: 6 | F13: =IF(A13="","",A13*E13) | G13: PPE
A14: 0 | B14: Kneepads | E14: 18 | F14: =IF(A14="","",A14*E14) | G14: PPE
A15: 0 | B15: Vacuum pump oil | E15: 12 | F15: =IF(A15="","",A15*E15) | G15: HVAC tools
A16: 0 | B16: Nitrogen purge consumables | E16: 25 | F16: =IF(A16="","",A16*E16) | G16: HVAC tools
A17: 0 | B17: Brazing tip / consumables kit | E17: 35 | F17: =IF(A17="","",A17*E17) | G17: HVAC tools
A18: 0 | B18: A2L-compatible gauge hose set (shop stock) | E18: 150 | F18: =IF(A18="","",A18*E18) | G18: A2L tools
A19: 0 | B19: Leak-detect fluid bottle | E19: 12 | F19: =IF(A19="","",A19*E19) | G19: HVAC tools
A20: 0 | B20: Flaring tool consumables | E20: 20 | F20: =IF(A20="","",A20*E20) | G20: HVAC tools
A21: 0 | B21: Tie wraps / fasteners pack | E21: 10 | F21: =IF(A21="","",A21*E21) | G21: Consumables

Sheet Summary
A1: Bruno AC Services LLC — SUMMARY (Method A)
A2: Overhead Absorption Rate: | E2: 0.25 | F2: OH (editable)
A4: G&A Expenses + Debt Service → absorbed via OH rate above
A7: Desired Profit Margin (of sales): | E7: 0.15 | F7: Profit (editable)
A9: Divisor for Method A = (1 − profit)
E11: =1-E7 | F11: ) → sales = cost × (1+OH) / (1−profit)
A12: NOTE: Single margin layer — Materials!B3 must stay 0; OH/profit only via Summary E2/E7 (Method A: cost*(1+OH)/(1-profit)). T&M does NOT use this sheet.
A14: Bruno AC Services LLC
F15: Job Number: | G15: ='Quote'!B6
F16: Customer: | G16: ='Quote'!B11
C20: Equip Cost: | D20: =LaborEquip!B15 | F20: with overhead & profit | H20: =IF(OR($E$7>=1,1-$E$7<=0),D20,(D20*(1+$E$2))/(1-$E$7))
C22: Labor Cost: | D22: =LaborEquip!B2 | F22: with overhead & profit | H22: =IF(OR($E$7>=1,1-$E$7<=0),D22,(D22*(1+$E$2))/(1-$E$7))
C24: Material Cost: | D24: =Materials!B2 | F24: with overhead & profit | H24: =IF(OR($E$7>=1,1-$E$7<=0),D24,(D24*(1+$E$2))/(1-$E$7))
C26: SubContractor Cost: | D26: =LaborEquip!B23 | F26: with overhead & profit | H26: =IF(OR($E$7>=1,1-$E$7<=0),D26,(D26*(1+$E$2))/(1-$E$7))
C28: Total Job Cost: | D28: =D20+D22+D24+D26 | G28: Sales Price (sum buckets) | H28: =SUM(H20:H26)
C31: Overhead Amount: | D31: =D28*E2 | G31: =E2
C33: Break Even Point: | D33: =D28+D31
C35: Profit Amount: | D35: =(D33/E11)-D33 | G35: =E7
C39: Final Sales Price (exact): | D39: =D33+D35 | E39: Also = H28 (bucket sum)
C40: Approved Change Orders: | D40: =ChangeOrders!B2
C41: Client Grand Total (ROUND sales + COs): | D41: =D42+D40
C42: Base Quote ROUND(sales): | D42: =ROUND(D39,0)
A44: Demo target (PWA seed): Material 6028 | Equip 600 | Labor 2712 | Cost 9340 | Sales 13735.294… | ROUND 13735
A45: Quote! mirrors D41 as QUOTE TOTAL. T&M sheet is independent (no OH&P).
A46: © 2026 Bruno AC Services LLC

Sheet Workers
A1: WORKERS — Burden (quote path) & Pay calculator (informational only)
A2: CRITICAL: Labor & Equip and Summary use BURDEN rates only. Changing Pay Rate / Tax Rate must NOT change Quote Total.
A4: BURDEN TABLE (feeds LaborEquip)
A11: Type | B11: Role label | C11: Straight $/hr | D11: OT mult | E11: DT mult | F11: OT $/hr | G11: DT $/hr
A12: Lead tech | B12: Lead tech | C12: 65 | D12: 1.5 | E12: 2 | F12: =C12*D12 | G12: =C12*E12
A13: Installer | B13: Installer | C13: 52 | D13: 1.5 | E13: 2 | F13: =C13*D13 | G13: =C13*E13
A14: Helper | B14: Helper | C14: 35 | D14: 1.5 | E14: 2 | F14: =C14*D14 | G14: =C14*E14
A15: Sheet-metal | B15: Sheet-metal | C15: 55 | D15: 1.5 | E15: 2 | F15: =C15*D15 | G15: =C15*E15
A16: Start-up | B16: Start-up | C16: 70 | D16: 1.5 | E16: 2 | F16: =C16*D16 | G16: =C16*E16
A19: PAY CALCULATOR (informational — does not feed Quote)
A20: Name | B20: Role | C20: Pay Rate $/hr | D20: Tax Rate % | E20: Net $/hr | F20: Day (8h) | G20: Week (40h)
A21: Lead Tech | B21: Lead tech | C21: 32 | D21: 0 | E21: =C21*(1-D21/100) | F21: =E21*8 | G21: =E21*40
A22: Installer | B22: Installer | C22: 28 | D22: 0 | E22: =C22*(1-D22/100) | F22: =E22*8 | G22: =E22*40
A23: Helper | B23: Helper | C23: 18 | D23: 0 | E23: =C23*(1-D23/100) | F23: =E23*8 | G23: =E23*40
A24: Sheet-metal | B24: Sheet-metal | C24: 30 | D24: 0 | E24: =C24*(1-D24/100) | F24: =E24*8 | G24: =E24*40
A25: Start-up | B25: Start-up | C25: 34 | D25: 0 | E25: =C25*(1-D25/100) | F25: =E25*8 | G25: =E25*40
A28: Tax stacking note (Dispatch / payroll estimate — not Method A)
A29: Federal % | B29: 0 | C29: State % | D29: 0 | E29: Local % | F29: 0
A30: Effective stacked % | B30: =(1-(1-B29/100)*(1-D29/100)*(1-F29/100))*100 | C30: Compound stack (not sum). Example 10+5+2 → 16.21%. Informational — not Method A.

Sheet TM
A1: T&M INVOICE — Time & Material (NO Method A OH&P)
A2: Honesty rule: T&M bills actual lines at agreed rates. Do NOT pull Summary sales as a fake T&M total.
A4: Date | B4: 2026-09-11
A5: Invoice #
A6: Customer | B6: Sample Residence — AC Changeout
A7: Job address | B7: 123 Maple Creek Ln, Austin, TX 78745
A9: EQUIPMENT / RENTAL LINES
A10: Qty | B10: Description | C10: Unit | D10: Rate | E10: Extension
E11: =IF(OR(A11="",D11=""),"",A11*D11)
E12: =IF(OR(A12="",D12=""),"",A12*D12)
E13: =IF(OR(A13="",D13=""),"",A13*D13)
E14: =IF(OR(A14="",D14=""),"",A14*D14)
E15: =IF(OR(A15="",D15=""),"",A15*D15)
A16: Equip subtotal | E16: =SUM(E11:E15)
A18: LABOR LINES
A19: Hours | B19: Description | C19: Tech | D19: Rate | E19: Extension
E20: =IF(OR(A20="",D20=""),"",A20*D20)
E21: =IF(OR(A21="",D21=""),"",A21*D21)
E22: =IF(OR(A22="",D22=""),"",A22*D22)
E23: =IF(OR(A23="",D23=""),"",A23*D23)
E24: =IF(OR(A24="",D24=""),"",A24*D24)
E25: =IF(OR(A25="",D25=""),"",A25*D25)
E26: =IF(OR(A26="",D26=""),"",A26*D26)
E27: =IF(OR(A27="",D27=""),"",A27*D27)
A28: Labor subtotal | E28: =SUM(E20:E27)
A30: MATERIALS (T&M)
A31: Qty | B31: Description | C31: Unit | D31: Cost | E31: Extension
E32: =IF(OR(A32="",D32=""),"",A32*D32)
E33: =IF(OR(A33="",D33=""),"",A33*D33)
E34: =IF(OR(A34="",D34=""),"",A34*D34)
E35: =IF(OR(A35="",D35=""),"",A35*D35)
E36: =IF(OR(A36="",D36=""),"",A36*D36)
E37: =IF(OR(A37="",D37=""),"",A37*D37)
E38: =IF(OR(A38="",D38=""),"",A38*D38)
E39: =IF(OR(A39="",D39=""),"",A39*D39)
A40: Material subtotal | E40: =SUM(E32:E39)
A42: Subcontractor lump | E42: 0
A43: T&M INVOICE TOTAL (no OH&P) | E43: =E16+E28+E40+E42
A45: Letterhead: Bruno AC Services LLC | Print as Invoice. Taxes not included unless listed.

Sheet PnL
A1: PROFIT & LOSS — Quoted vs Billed vs Actual
A3: QUOTED (from Summary Method A)
A4: Quoted Sales (exact) | B4: =Summary!D39
A5: Quoted / Base ROUND | B5: =Summary!D42
A6: Quote Total (+ COs) | B6: =Summary!D41
A7: Quoted Job Cost | B7: =Summary!D28
A8: Quoted Gross (Sales − Cost) | B8: =B4-B7
A10: BILLED (from T&M)
A11: T&M Billed Total | B11: =TM!E43 | C11: Override billed (optional)
A12: Billed used | B12: =IF(D11="",B11,D11)
A14: ACTUAL COSTS (overrides — empty Actual Material defaults to Material Cost)
A15: Actual Labor | B15: 0
A16: Actual Equip | B16: 0
A17: Actual Material (blank → use quoted mat) | C17: =IF(B17="",Summary!D24,B17)
A18: Actual Sub | B18: 0
A19: Actual Other | B19: 0
A20: Actual Cost Total | B20: =B15+B16+C17+B18+B19
A21: Note: If Actual Labor/Equip left at 0, margin looks artificially high — enter actuals for real P&L.
A23: VARIANCE
A24: Quoted vs Billed | B24: =B12-B6
A25: Billed − Actual Cost | B25: =B12-B20
A26: Quoted Sales − Actual Cost | B26: =B4-B20

Sheet ChangeOrders
A1: CHANGE ORDERS
A2: Approved COs TOTAL (only status=Approved) | B2: =SUMIF(E12:E100,"Approved",D12:D100) | C2: ← feeds Summary!D40 — draft/submitted/rejected/void excluded
A3: CO amounts are dollar adds to Quote Total (not re-run through Method A unless shop policy changes).
A11: CO # | B11: Date | C11: Description | D11: Amount | E11: Status | F11: Notes
A12: CO-001 | B12: 2026-09-11 | C12: Optional UV IAQ add (demo draft — not in Quote Total) | D12: 350 | E12: Draft | F12: Status must be Approved to affect Quote Total
A32: Allowed statuses: Draft | Submitted | Approved | Rejected | Void

Sheet Reference
A1: REFERENCE — Informational only (does NOT rewrite labor, qty, OH%, or Method A)
A2: No NEC ampacity / conduit fill / motor FLA tables. HVAC codes & efficiency notes for Texas estimators.
A4: SECTION | B4: CONTENT | C4: SOURCE / NOTE
A5: SECO Energy (statewide) | B5: Statewide commercial baseline remains 2015 IECC (34 TAC §19.53). Single-family statewide baseline 2015 IRC Chapter 11. 2021/2024 IECC NOT verified as statewide for 2026 — cities often stricter (check AHJ). | C5: SECO / Comptroller
A6: TDLR ACR codes | B6: Effective Sept 1, 2026: TDLR adopts 2024 IRC, 2024 IMC, 2024 IFGC, 2024 UMC (16 TAC §75.110). 2021 editions through Aug 31, 2026; work permitted/started before 2026-09-01 may finish under 2021. ASHRAE 15/34 refs update 2022→2024. | C6: Texas Register / TDLR
A7: SEER2 — Southeast (TX) | B7: Split AC <45 kBtu/h: 14.3 SEER2 regional install floor. Split AC ≥45 kBtu/h: 13.8 SEER2. Split HP: 14.3 SEER2 / 7.5 HSPF2 national. Package metrics differ — see 10 CFR §430.32(c). Record OEM/AHRI ratings; do not auto-fail quotes in software. | C7: DOE / eCFR
A8: ENERGY STAR CAC | B8: ENERGY STAR Central Air Conditioner (CAC) product category sunset — verify current ENERGY STAR HVAC categories/specs before claiming rebate eligibility. Prefer manufacturer published SEER2/HSPF2. | C8: ENERGY STAR program notes
A9: Refrigerants / AIM Act | B9: New residential/light-commercial AC&HP: GWP ≤700 path; common A2L refrigerants R-454B and R-32 for new installs. R-410A remains relevant for SERVICE / legacy inventory. EPA May 2026 action described inventory install flexibility for pre-2025 components — confirm current EPA text. EPA Section 608 certification required for handling. | C9: EPA Technology Transitions
A10: A2L extras | B10: Mildly flammable (A2L): use compatible gauges/recovery, leak-detection where required by OEM/code, trained techs. Catalog lines are stubs — follow OEM install instructions. | C10: OEM / ASHRAE 15
A11: Rough sizing disclaimer | B11: Rules of thumb (tons ≈ sq ft / X) are ROUGH ONLY. Manual J (load), Manual S (equipment), Manual D (duct) required for proper design. This workbook never auto-applies sizing to qty or price. | C11: ACC A / industry practice
A12: Install checklist (text) | B12: Recover old refrigerant (608) → set pad/level → place outdoor → set indoor/AHU → line set / braze or OEM joints → pressure test / nitrogen → evacuate to micron target per OEM → open valves / charge per OEM → condensate trap/float/secondary pan → thermostat → start-up / airflow check → customer walkthrough. | C12: Shop process
A13: Clearances / airflow | B13: Outdoor clearances, indoor return/supply, and filter access per manufacturer & code. Verify on site — do not invent IMC section numbers in this sheet. | C13: OEM / AHJ
A14: Electrical coordination | B14: Disconnects/whips are catalog support lines only. TDLR electrician rules adopted 2026 NEC (eff. Sept 1, 2026) with modified outdoor HVAC GFCI exception — coordinate with electrical trade; do not auto-pick breakers here. | C14: TDLR Ch.73 note
A15: Job settings note | B15: Default jurisdiction: Texas / Austin area. Code note on Quote/Cover is informational print text — changing it must not rewrite Method A. | C15: App policy
A17: © 2026 Bruno AC Services LLC — Reference is not engineering, legal, or code compliance advice.

Sheet Dispatch
A1: DISPATCH — Service call day journal (light)
A2: Selected date | B2: 2026-09-11
A3: Tax effective % (from Workers) | B3: =Workers!B30 | C3: Informational payroll estimate — does not change Method A quote
A5: Date | B5: Tech | C5: Customer / Call | D5: Hours | E5: Gross $ | F5: Net $ | G5: Status | H5: Type | I5: Notes
F6: =IF(E6="","",E6*(1-$B$3/100))
F7: =IF(E7="","",E7*(1-$B$3/100))
F8: =IF(E8="","",E8*(1-$B$3/100))
F9: =IF(E9="","",E9*(1-$B$3/100))
F10: =IF(E10="","",E10*(1-$B$3/100))
F11: =IF(E11="","",E11*(1-$B$3/100))
F12: =IF(E12="","",E12*(1-$B$3/100))
F13: =IF(E13="","",E13*(1-$B$3/100))
F14: =IF(E14="","",E14*(1-$B$3/100))
F15: =IF(E15="","",E15*(1-$B$3/100))
F16: =IF(E16="","",E16*(1-$B$3/100))
F17: =IF(E17="","",E17*(1-$B$3/100))
... F25: =IF(E25="","",E25*(1-$B$3/100))
A28: Day totals | D28: =SUM(D6:D25) | E28: =SUM(E6:E25) | F28: =SUM(F6:F25)
A30: Call types: Service | Maintenance | Warranty | Install support | Estimate
A31: Statuses: Scheduled | En route | Complete | Callback | Cancelled
